<?xml version="1.0"?>
<robot xmlns:xacro="http://www.ros.org/wiki/xacro">
    <!-- Generic Thruster Macro -->
    <xacro:macro name="thruster" params="name parent xyz rpy">
        
        <joint name="${name}_joint" type="continuous">
            <parent link="${parent}"/>
            <child link="${name}"/>
            <origin xyz="${xyz}" rpy="${rpy}"/>
        </joint>

        <link name="${name}">
            <visual>
                <origin xyz="0 0 0" rpy="0 0 0" />
                <geometry>
                    <cylinder length="0.1" radius="0.05" />
                </geometry>
                <material name="blue">
                    <color rgba="0.0 0.0 1.0 0.0"/>
                </material>
            </visual>

            <inertial>
                <mass value="0.5"/>
                <origin xyz="0 0 0" rpy="0 0 0"/>
                <inertia ixx="0.0001" ixy="0" ixz="0" iyy="0.0001" iyz="0" izz="0.0001"/>
            </inertial>
        </link>
    </xacro:macro>

</robot>